Workbook

Sheet ReadMe_Methodology
A1: Naukri Saaf — Ghost Job Listing Detector
A2: Real scraped data (LinkedIn + Indeed + Glassdoor via Apify) | Combined Master Workbook
A5: WHAT THIS WORKBOOK IS
A6: This workbook analyzes 3,000 REAL job postings scraped from three platforms to surface listings that
A7: look statistically like "ghost jobs" (postings that are live but not genuinely hiring).
A9: IMPORTANT — READ BEFORE TRUSTING ANY GHOST LABEL
A10: This dataset has NO verified ground truth. Nobody confirmed with these companies whether a given
A11: listing was real or fake. "ghost_label" is a TRANSPARENT PROXY built from 5 observable signals below —
A12: it is a heuristic risk score, not a fact. Treat "Likely Ghost" as "worth a second look," not "confirmed fake."
A14: v2 CORRECTION (why this version differs from the first draft)
A15: The first draft used GLOBAL (whole-dataset) thresholds for 3 of the 5 signals. That silently broke cross-
A16: platform fairness: Indeed jobs are scraped almost the same day they are posted (avg days_live ~0.8), so
... A80: salary figures as directional, not representative of the full market.

Sheet Executive_Dashboard
A1: Executive KPI Dashboard
A2: Naukri Saaf — Combined view across LinkedIn, Indeed & Glassdoor (3,000 real listings)
A4: Total Listings | C4: Likely Ghost | E4: Uncertain | G4: Likely Genuine | I4: Ghost Rate %
A5: =COUNTA(Combined_Data!$A$2:$A$3001) -> 3000 | C5: =COUNTIF(Combined_Data!$AG$2:$AG$3001,"Likely Ghost") -> 146 | E5: =COUNTIF(Combined_Data!$AG$2:$AG$3001,"Uncertain") -> 1543 | G5: =COUNTIF(Combined_Data!$AG$2:$AG$3001,"Likely Genuine") -> 1311 | I5: =COUNTIF(Combined_Data!$AG$2:$AG$3001,"Likely Ghost")/COUNTA(Combined_Data!$A$2:$A$3001)*100 -> 4.8666667
A9: Platform-wise Comparison
A10: Portal | B10: Total Listings | C10: Likely Ghost | D10: Uncertain | E10: Likely Genuine | F10: Ghost Rate % | G10: Avg Days Live | H10: Avg Ghost Score %
A11: LinkedIn | B11: =COUNTIF(Combined_Data!$B$2:$B$3001,"LinkedIn") -> 1000 | C11: =COUNTIFS(Combined_Data!$B$2:$B$3001,"LinkedIn",Combined_Data!$AG$2:$AG$3001,"Likely Ghost") -> 77 | D11: =COUNTIFS(Combined_Data!$B$2:$B$3001,"LinkedIn",Combined_Data!$AG$2:$AG$3001,"Uncertain") -> 669 | E11: =COUNTIFS(Combined_Data!$B$2:$B$3001,"LinkedIn",Combined_Data!$AG$2:$AG$3001,"Likely Genuine") -> 254 | F11: =C11/B11*100 -> 7.7 | G11: =AVERAGEIF(Combined_Data!$B$2:$B$3001,"LinkedIn",Combined_Data!$K$2:$K$3001) -> 40.734 | H11: =AVERAGEIF(Combined_Data!$B$2:$B$3001,"LinkedIn",Combined_Data!$AF$2:$AF$3001) -> 33.1397
A12: Indeed | B12: =COUNTIF(Combined_Data!$B$2:$B$3001,"Indeed") -> 1000 | C12: =COUNTIFS(Combined_Data!$B$2:$B$3001,"Indeed",Combined_Data!$AG$2:$AG$3001,"Likely Ghost") -> 44 | D12: =COUNTIFS(Combined_Data!$B$2:$B$3001,"Indeed",Combined_Data!$AG$2:$AG$3001,"Uncertain") -> 435 | E12: =COUNTIFS(Combined_Data!$B$2:$B$3001,"Indeed",Combined_Data!$AG$2:$AG$3001,"Likely Genuine") -> 521 | F12: =C12/B12*100 -> 4.4 | G12: =AVERAGEIF(Combined_Data!$B$2:$B$3001,"Indeed",Combined_Data!$K$2:$K$3001) -> 0.7631 | H12: =AVERAGEIF(Combined_Data!$B$2:$B$3001,"Indeed",Combined_Data!$AF$2:$AF$3001) -> 24.1054
A13: Glassdoor | B13: =COUNTIF(Combined_Data!$B$2:$B$3001,"Glassdoor") -> 1000 | C13: =COUNTIFS(Combined_Data!$B$2:$B$3001,"Glassdoor",Combined_Data!$AG$2:$AG$3001,"Likely Ghost") -> 25 | D13: =COUNTIFS(Combined_Data!$B$2:$B$3001,"Glassdoor",Combined_Data!$AG$2:$AG$3001,"Uncertain") -> 439 | E13: =COUNTIFS(Combined_Data!$B$2:$B$3001,"Glassdoor",Combined_Data!$AG$2:$AG$3001,"Likely Genuine") -> 536 | F13: =C13/B13*100 -> 2.5 | G13: =AVERAGEIF(Combined_Data!$B$2:$B$3001,"Glassdoor",Combined_Data!$K$2:$K$3001) -> 61.334 | H13: =AVERAGEIF(Combined_Data!$B$2:$B$3001,"Glassdoor",Combined_Data!$AF$2:$AF$3001) -> 21.805
A14: TOTAL | B14: =SUM(B11:B13) -> 3000 | C14: =SUM(C11:C13) -> 146 | D14: =SUM(D11:D13) -> 1543 | E14: =SUM(E11:E13) -> 1311 | F14: =C14/B14*100 -> 4.8666667 | G14: =AVERAGE(Combined_Data!$K$2:$K$3001) -> 34.277033 | H14: =AVERAGE(Combined_Data!$AF$2:$AF$3001) -> 26.350033
A16: Overall Ghost Label Split
A17: Likely Ghost | B17: =COUNTIF(Combined_Data!$AG$2:$AG$3001,"Likely Ghost") -> 146
A18: Uncertain | B18: =COUNTIF(Combined_Data!$AG$2:$AG$3001,"Uncertain") -> 1543
A19: Likely Genuine | B19: =COUNTIF(Combined_Data!$AG$2:$AG$3001,"Likely Genuine") -> 1311

Sheet Company_Explorer
A1: Interactive Company & Job Explorer
A2: Pick a Company / Platform / Role / Ghost Label below — every KPI, chart and row in this sheet updates instantly. No macros, no Excel 365 dynamic-array functions required.
A4: FILTERS (click cell → choose from dropdown)
A5: Company | B5: Infosys | F5: Tip: leave any filter on "All ..." to ignore it. Company list is sorted by posting volume (most-active employers first).
A6: Platform | B6: All Platforms
A7: Role Bucket | B7: All Roles
A8: Ghost Label | B8: All Ghost Labels
A9: KPI SUMMARY (for current filter selection)
A10: Matching Listings | C10: Likely Ghost | E10: Ghost Rate % | G10: Avg Days Live | I10: Avg Ghost Score % | K10: Avg Est. Annual Salary (disclosed)
A11: =SUM(Combined_Data!$AI$2:$AI$3001) -> 24 | C11: =SUMPRODUCT((Combined_Data!$AG$2:$AG$3001="Likely Ghost")*Combined_Data!$AI$2:$AI$3001) -> 0 | E11: =IFERROR(C11/A11*100,0) -> 0 | G11: =IFERROR(SUMPRODUCT(Combined_Data!$K$2:$K$3001*Combined_Data!$AI$2:$AI$3001)/A11,0) -> 3.4083333 | I11: =IFERROR(SUMPRODUCT(Combined_Data!$AF$2:$AF$3001*Combined_Data!$AI$2:$AI$3001)/A11,0) -> 29.195833 | K11: =IFERROR(SUMPRODUCT((Combined_Data!$T$2:$T$3001=TRUE())*Combined_Data!$AI$2:$AI$3001*Combined_Data!$S$2:$S$3001)/SUMPRODUCT((Combined_Data!$T$2:$T$3001=TRUE())*Combined_Data!$AI$2:$AI$3001),0) -> 0
A13: Platform Split (current filter) | F13: Ghost Label Split (current filter)
A14: Portal | B14: Count | F14: Ghost Label | G14: Count
A15: LinkedIn | B15: =SUMPRODUCT((Combined_Data!$B$2:$B$3001="LinkedIn")*Combined_Data!$AI$2:$AI$3001) -> 8 | F15: Likely Ghost | G15: =SUMPRODUCT((Combined_Data!$AG$2:$AG$3001="Likely Ghost")*Combined_Data!$AI$2:$AI$3001) -> 0
A16: Indeed | B16: =SUMPRODUCT((Combined_Data!$B$2:$B$3001="Indeed")*Combined_Data!$AI$2:$AI$3001) -> 16 | F16: Uncertain | G16: =SUMPRODUCT((Combined_Data!$AG$2:$AG$3001="Uncertain")*Combined_Data!$AI$2:$AI$3001) -> 18
A17: Glassdoor | B17: =SUMPRODUCT((Combined_Data!$B$2:$B$3001="Glassdoor")*Combined_Data!$AI$2:$AI$3001) -> 0 | F17: Likely Genuine | G17: =SUMPRODUCT((Combined_Data!$AG$2:$AG$3001="Likely Genuine")*Combined_Data!$AI$2:$AI$3001) -> 6
A33: DETAIL: MATCHING LISTINGS (showing up to first 400 matches — total match count is in the KPI above)
A34: Job Title | B34: Company Name | C34: Portal | D34: Role Bucket | E34: City | F34: Posted Date | G34: Days Live | H34: Experience Level | I34: Salary Disclosed? | J34: Est. Annual Salary | K34: Ghost Score % | L34: Ghost Label | M34: Source URL
A35: =IFERROR(INDEX(Combined_Data!$C:$C,$O35+1),"") -> Full stack Developer (Python with React) | B35: =IFERROR(INDEX(Combined_Data!$E:$E,$O35+1),"") -> Infosys | C35: =IFERROR(INDEX(Combined_Data!$B:$B,$O35+1),"") -> LinkedIn | D35: =IFERROR(INDEX(Combined_Data!$D:$D,$O35+1),"") -> Full Stack Engineer | E35: =IFERROR(INDEX(Combined_Data!$G:$G,$O35+1),"") -> Bengaluru East | F35: =IFERROR(INDEX(Combined_Data!$I:$I,$O35+1),"") -> 46205 | G35: =IFERROR(INDEX(Combined_Data!$K:$K,$O35+1),"") -> 5 | H35: =IFERROR(INDEX(Combined_Data!$M:$M,$O35+1),"") -> Not Applicable | I35: =IFERROR(INDEX(Combined_Data!$N:$N,$O35+1),"") -> FALSE | J35: =IFERROR(INDEX(Combined_Data!$S:$S,$O35+1),"") -> 0 | K35: =IFERROR(INDEX(Combined_Data!$AF:$AF,$O35+1),"") -> 14.3 | L35: =IFERROR(INDEX(Combined_Data!$AG:$AG,$O35+1),"") -> Likely Genuine | M35: =IFERROR(INDEX(Combined_Data!$AH:$AH,$O35+1),"") -> https://in.linkedin.com/jobs/view/full-stack-developer-python-with-react-at-infosys-4435263024?trk=public_jobs_topcard-title | O35: =IFERROR(_xlfn.AGGREGATE(15,6,(ROW(Combined_Data!$AI$2:$AI$3001)-1)/(Combined_Data!$AI$2:$AI$3001),1),"") -> 656
A36: =IFERROR(INDEX(Combined_Data!$C:$C,$O36+1),"") -> Java Developer | B36: =IFERROR(INDEX(Combined_Data!$E:$E,$O36+1),"") -> Infosys | C36: =IFERROR(INDEX(Combined_Data!$B:$B,$O36+1),"") -> LinkedIn | D36: =IFERROR(INDEX(Combined_Data!$D:$D,$O36+1),"") -> Software Engineer | E36: =IFERROR(INDEX(Combined_Data!$G:$G,$O36+1),"") -> Bengaluru East | F36: =IFERROR(INDEX(Combined_Data!$I:$I,$O36+1),"") -> 46203 | G36: =IFERROR(INDEX(Combined_Data!$K:$K,$O36+1),"") -> 7 | H36: =IFERROR(INDEX(Combined_Data!$M:$M,$O36+1),"") -> Not Applicable | I36: =IFERROR(INDEX(Combined_Data!$N:$N,$O36+1),"") -> FALSE | J36: =IFERROR(INDEX(Combined_Data!$S:$S,$O36+1),"") -> 0 | K36: =IFERROR(INDEX(Combined_Data!$AF:$AF,$O36+1),"") -> 28.6 | L36: =IFERROR(INDEX(Combined_Data!$AG:$AG,$O36+1),"") -> Uncertain | M36: =IFERROR(INDEX(Combined_Data!$AH:$AH,$O36+1),"") -> https://in.linkedin.com/jobs/view/java-developer-at-infosys-4434348807?trk=public_jobs_topcard-title | O36: =IFERROR(_xlfn.AGGREGATE(15,6,(ROW(Combined_Data!$AI$2:$AI$3001)-1)/(Combined_Data!$AI$2:$AI$3001),2),"") -> 661
A37: =IFERROR(INDEX(Combined_Data!$C:$C,$O37+1),"") -> Java Developer | B37: =IFERROR(INDEX(Combined_Data!$E:$E,$O37+1),"") -> Infosys | C37: =IFERROR(INDEX(Combined_Data!$B:$B,$O37+1),"") -> LinkedIn | D37: =IFERROR(INDEX(Combined_Data!$D:$D,$O37+1),"") -> Software Engineer | E37: =IFERROR(INDEX(Combined_Data!$G:$G,$O37+1),"") -> Bengaluru East | F37: =IFERROR(INDEX(Combined_Data!$I:$I,$O37+1),"") -> 46203 | G37: =IFERROR(INDEX(Combined_Data!$K:$K,$O37+1),"") -> 7 | H37: =IFERROR(INDEX(Combined_Data!$M:$M,$O37+1),"") -> Not Applicable | I37: =IFERROR(INDEX(Combined_Data!$N:$N,$O37+1),"") -> FALSE | J37: =IFERROR(INDEX(Combined_Data!$S:$S,$O37+1),"") -> 0 | K37: =IFERROR(INDEX(Combined_Data!$AF:$AF,$O37+1),"") -> 14.3 | L37: =IFERROR(INDEX(Combined_Data!$AG:$AG,$O37+1),"") -> Likely Genuine | M37: =IFERROR(INDEX(Combined_Data!$AH:$AH,$O37+1),"") -> https://in.linkedin.com/jobs/view/java-developer-at-infosys-4434302723?trk=public_jobs_topcard-title | O37: =IFERROR(_xlfn.AGGREGATE(15,6,(ROW(Combined_Data!$AI$2:$AI$3001)-1)/(Combined_Data!$AI$2:$AI$3001),3),"") -> 663
A38: =IFERROR(INDEX(Combined_Data!$C:$C,$O38+1),"") -> Java Springboot Developer | B38: =IFERROR(INDEX(Combined_Data!$E:$E,$O38+1),"") -> Infosys | C38: =IFERROR(INDEX(Combined_Data!$B:$B,$O38+1),"") -> LinkedIn | D38: =IFERROR(INDEX(Combined_Data!$D:$D,$O38+1),"") -> Software Engineer | E38: =IFERROR(INDEX(Combined_Data!$G:$G,$O38+1),"") -> Bengaluru East | F38: =IFERROR(INDEX(Combined_Data!$I:$I,$O38+1),"") -> 46200 | G38: =IFERROR(INDEX(Combined_Data!$K:$K,$O38+1),"") -> 10 | H38: =IFERROR(INDEX(Combined_Data!$M:$M,$O38+1),"") -> Not Applicable | I38: =IFERROR(INDEX(Combined_Data!$N:$N,$O38+1),"") -> FALSE | J38: =IFERROR(INDEX(Combined_Data!$S:$S,$O38+1),"") -> 0 | K38: =IFERROR(INDEX(Combined_Data!$AF:$AF,$O38+1),"") -> 14.3 | L38: =IFERROR(INDEX(Combined_Data!$AG:$AG,$O38+1),"") -> Likely Genuine | M38: =IFERROR(INDEX(Combined_Data!$AH:$AH,$O38+1),"") -> https://in.linkedin.com/jobs/view/java-springboot-developer-at-infosys-4433476671?trk=public_jobs_topcard-title | O38: =IFERROR(_xlfn.AGGREGATE(15,6,(ROW(Combined_Data!$AI$2:$AI$3001)-1)/(Combined_Data!$AI$2:$AI$3001),4),"") -> 687
A39: =IFERROR(INDEX(Combined_Data!$C:$C,$O39+1),"") -> Java Developer | B39: =IFERROR(INDEX(Combined_Data!$E:$E,$O39+1),"") -> Infosys | C39: =IFERROR(INDEX(Combined_Data!$B:$B,$O39+1),"") -> LinkedIn | D39: =IFERROR(INDEX(Combined_Data!$D:$D,$O39+1),"") -> Software Engineer | E39: =IFERROR(INDEX(Combined_Data!$G:$G,$O39+1),"") -> Bengaluru East | F39: =IFERROR(INDEX(Combined_Data!$I:$I,$O39+1),"") -> 46201 | G39: =IFERROR(INDEX(Combined_Data!$K:$K,$O39+1),"") -> 9 | H39: =IFERROR(INDEX(Combined_Data!$M:$M,$O39+1),"") -> Not Applicable | I39: =IFERROR(INDEX(Combined_Data!$N:$N,$O39+1),"") -> FALSE | J39: =IFERROR(INDEX(Combined_Data!$S:$S,$O39+1),"") -> 0 | K39: =IFERROR(INDEX(Combined_Data!$AF:$AF,$O39+1),"") -> 14.3 | L39: =IFERROR(INDEX(Combined_Data!$AG:$AG,$O39+1),"") -> Likely Genuine | M39: =IFERROR(INDEX(Combined_Data!$AH:$AH,$O39+1),"") -> https://in.linkedin.com/jobs/view/java-developer-at-infosys-4433627403?trk=public_jobs_topcard-title | O39: =IFERROR(_xlfn.AGGREGATE(15,6,(ROW(Combined_Data!$AI$2:$AI$3001)-1)/(Combined_Data!$AI$2:$AI$3001),5),"") -> 699
A40: =IFERROR(INDEX(Combined_Data!$C:$C,$O40+1),"") -> React.js Developer | B40: =IFERROR(INDEX(Combined_Data!$E:$E,$O40+1),"") -> Infosys | C40: =IFERROR(INDEX(Combined_Data!$B:$B,$O40+1),"") -> LinkedIn | D40: =IFERROR(INDEX(Combined_Data!$D:$D,$O40+1),"") -> Software Engineer | E40: =IFERROR(INDEX(Combined_Data!$G:$G,$O40+1),"") -> Hyderabad | F40: =IFERROR(INDEX(Combined_Data!$I:$I,$O40+1),"") -> 46200 | G40: =IFERROR(INDEX(Combined_Data!$K:$K,$O40+1),"") -> 10 | H40: =IFERROR(INDEX(Combined_Data!$M:$M,$O40+1),"") -> Not Applicable | I40: =IFERROR(INDEX(Combined_Data!$N:$N,$O40+1),"") -> FALSE | J40: =IFERROR(INDEX(Combined_Data!$S:$S,$O40+1),"") -> 0 | K40: =IFERROR(INDEX(Combined_Data!$AF:$AF,$O40+1),"") -> 14.3 | L40: =IFERROR(INDEX(Combined_Data!$AG:$AG,$O40+1),"") -> Likely Genuine | M40: =IFERROR(INDEX(Combined_Data!$AH:$AH,$O40+1),"") -> https://in.linkedin.com/jobs/view/react-js-developer-at-infosys-4433471833?trk=public_jobs_topcard-title | O40: =IFERROR(_xlfn.AGGREGATE(15,6,(ROW(Combined_Data!$AI$2:$AI$3001)-1)/(Combined_Data!$AI$2:$AI$3001),6),"") -> 714
A41: =IFERROR(INDEX(Combined_Data!$C:$C,$O41+1),"") -> Node JS, Graph QL, AWS/Azure Developer | B41: =IFERROR(INDEX(Combined_Data!$E:$E,$O41+1),"") -> Infosys | C41: =IFERROR(INDEX(Combined_Data!$B:$B,$O41+1),"") -> LinkedIn | D41: =IFERROR(INDEX(Combined_Data!$D:$D,$O41+1),"") -> Software Engineer | E41: =IFERROR(INDEX(Combined_Data!$G:$G,$O41+1),"") -> Pune Division | F41: =IFERROR(INDEX(Combined_Data!$I:$I,$O41+1),"") -> 46203 | G41: =IFERROR(INDEX(Combined_Data!$K:$K,$O41+1),"") -> 7 | H41: =IFERROR(INDEX(Combined_Data!$M:$M,$O41+1),"") -> Not Applicable | I41: =IFERROR(INDEX(Combined_Data!$N:$N,$O41+1),"") -> FALSE | J41: =IFERROR(INDEX(Combined_Data!$S:$S,$O41+1),"") -> 0 | K41: =IFERROR(INDEX(Combined_Data!$AF:$AF,$O41+1),"") -> 14.3 | L41: =IFERROR(INDEX(Combined_Data!$AG:$AG,$O41+1),"") -> Likely Genuine | M41: =IFERROR(INDEX(Combined_Data!$AH:$AH,$O41+1),"") -> https://in.linkedin.com/jobs/view/node-js-graph-ql-aws-azure-developer-at-infosys-4434341886?trk=public_jobs_topcard-title | O41: =IFERROR(_xlfn.AGGREGATE(15,6,(ROW(Combined_Data!$AI$2:$AI$3001)-1)/(Combined_Data!$AI$2:$AI$3001),7),"") -> 750
A42: =IFERROR(INDEX(Combined_Data!$C:$C,$O42+1),"") -> Java full stack, React Developer | B42: =IFERROR(INDEX(Combined_Data!$E:$E,$O42+1),"") -> Infosys | C42: =IFERROR(INDEX(Combined_Data!$B:$B,$O42+1),"") -> LinkedIn | D42: =IFERROR(INDEX(Combined_Data!$D:$D,$O42+1),"") -> Full Stack Engineer | E42: =IFERROR(INDEX(Combined_Data!$G:$G,$O42+1),"") -> Bengaluru East | F42: =IFERROR(INDEX(Combined_Data!$I:$I,$O42+1),"") -> 46203 | G42: =IFERROR(INDEX(Combined_Data!$K:$K,$O42+1),"") -> 7 | H42: =IFERROR(INDEX(Combined_Data!$M:$M,$O42+1),"") -> Not Applicable | I42: =IFERROR(INDEX(Combined_Data!$N:$N,$O42+1),"") -> FALSE | J42: =IFERROR(INDEX(Combined_Data!$S:$S,$O42+1),"") -> 0 | K42: =IFERROR(INDEX(Combined_Data!$AF:$AF,$O42+1),"") -> 28.6 | L42: =IFERROR(INDEX(Combined_Data!$AG:$AG,$O42+1),"") -> Uncertain | M42: =IFERROR(INDEX(Combined_Data!$AH:$AH,$O42+1),"") -> https://in.linkedin.com/jobs/view/java-full-stack-react-developer-at-infosys-4434904987?trk=public_jobs_topcard-title | O42: =IFERROR(_xlfn.AGGREGATE(15,6,(ROW(Combined_Data!$AI$2:$AI$3001)-1)/(Combined_Data!$AI$2:$AI$3001),8),"") -> 839
A43: =IFERROR(INDEX(Combined_Data!$C:$C,$O43+1),"") -> Healthcare Business Analyst | B43: =IFERROR(INDEX(Combined_Data!$E:$E,$O43+1),"") -> Infosys | C43: =IFERROR(INDEX(Combined_Data!$B:$B,$O43+1),"") -> Indeed | D43: =IFERROR(INDEX(Combined_Data!$D:$D,$O43+1),"") -> Data Analyst | E43: =IFERROR(INDEX(Combined_Data!$G:$G,$O43+1),"") -> Not Specified | F43: =IFERROR(INDEX(Combined_Data!$I:$I,$O43+1),"") -> 46210.222 | G43: =IFERROR(INDEX(Combined_Data!$K:$K,$O43+1),"") -> 0.1 | H43: =IFERROR(INDEX(Combined_Data!$M:$M,$O43+1),"") -> Not Captured by Scraper | I43: =IFERROR(INDEX(Combined_Data!$N:$N,$O43+1),"") -> FALSE | J43: =IFERROR(INDEX(Combined_Data!$S:$S,$O43+1),"") -> 0 | K43: =IFERROR(INDEX(Combined_Data!$AF:$AF,$O43+1),"") -> 28.6 | L43: =IFERROR(INDEX(Combined_Data!$AG:$AG,$O43+1),"") -> Uncertain | M43: =IFERROR(INDEX(Combined_Data!$AH:$AH,$O43+1),"") -> https://indeed.com/viewjob?jk=45af8ba21046d880 | O43: =IFERROR(_xlfn.AGGREGATE(15,6,(ROW(Combined_Data!$AI$2:$AI$3001)-1)/(Combined_Data!$AI$2:$AI$3001),9),"") -> 1035
A44: =IFERROR(INDEX(Combined_Data!$C:$C,$O44+1),"") -> Python & InManta Automation | B44: =IFERROR(INDEX(Combined_Data!$E:$E,$O44+1),"") -> Infosys | C44: =IFERROR(INDEX(Combined_Data!$B:$B,$O44+1),"") -> Indeed | D44: =IFERROR(INDEX(Combined_Data!$D:$D,$O44+1),"") -> Other | E44: =IFERROR(INDEX(Combined_Data!$G:$G,$O44+1),"") -> Not Specified | F44: =IFERROR(INDEX(Combined_Data!$I:$I,$O44+1),"") -> 46210.223 | G44: =IFERROR(INDEX(Combined_Data!$K:$K,$O44+1),"") -> 0.1 | H44: =IFERROR(INDEX(Combined_Data!$M:$M,$O44+1),"") -> Not Captured by Scraper | I44: =IFERROR(INDEX(Combined_Data!$N:$N,$O44+1),"") -> FALSE | J44: =IFERROR(INDEX(Combined_Data!$S:$S,$O44+1),"") -> 0 | K44: =IFERROR(INDEX(Combined_Data!$AF:$AF,$O44+1),"") -> 28.6 | L44: =IFERROR(INDEX(Combined_Data!$AG:$AG,$O44+1),"") -> Uncertain | M44: =IFERROR(INDEX(Combined_Data!$AH:$AH,$O44+1),"") -> https://indeed.com/viewjob?jk=13396b5c08f1e021 | O44: =IFERROR(_xlfn.AGGREGATE(15,6,(ROW(Combined_Data!$AI$2:$AI$3001)-1)/(Combined_Data!$AI$2:$AI$3001),10),"") -> 1153
A45: =IFERROR(INDEX(Combined_Data!$C:$C,$O45+1),"") -> Agentic AI Engineer | B45: =IFERROR(INDEX(Combined_Data!$E:$E,$O45+1),"") -> Infosys | C45: =IFERROR(INDEX(Combined_Data!$B:$B,$O45+1),"") -> Indeed | D45: =IFERROR(INDEX(Combined_Data!$D:$D,$O45+1),"") -> ML Engineer | E45: =IFERROR(INDEX(Combined_Data!$G:$G,$O45+1),"") -> Not Specified | F45: =IFERROR(INDEX(Combined_Data!$I:$I,$O45+1),"") -> 46210.223 | G45: =IFERROR(INDEX(Combined_Data!$K:$K,$O45+1),"") -> 0.1 | H45: =IFERROR(INDEX(Combined_Data!$M:$M,$O45+1),"") -> Not Captured by Scraper | I45: =IFERROR(INDEX(Combined_Data!$N:$N,$O45+1),"") -> FALSE | J45: =IFERROR(INDEX(Combined_Data!$S:$S,$O45+1),"") -> 0 | K45: =IFERROR(INDEX(Combined_Data!$AF:$AF,$O45+1),"") -> 28.6 | L45: =IFERROR(INDEX(Combined_Data!$AG:$AG,$O45+1),"") -> Uncertain | M45: =IFERROR(INDEX(Combined_Data!$AH:$AH,$O45+1),"") -> https://indeed.com/viewjob?jk=63743131dcf8d453 | O45: =IFERROR(_xlfn.AGGREGATE(15,6,(ROW(Combined_Data!$AI$2:$AI$3001)-1)/(Combined_Data!$AI$2:$AI$3001),11),"") -> 1154
A46: =IFERROR(INDEX(Combined_Data!$C:$C,$O46+1),"") -> Agentic AI Engineer | B46: =IFERROR(INDEX(Combined_Data!$E:$E,$O46+1),"") -> Infosys | C46: =IFERROR(INDEX(Combined_Data!$B:$B,$O46+1),"") -> Indeed | D46: =IFERROR(INDEX(Combined_Data!$D:$D,$O46+1),"") -> ML Engineer | E46: =IFERROR(INDEX(Combined_Data!$G:$G,$O46+1),"") -> Not Specified | F46: =IFERROR(INDEX(Combined_Data!$I:$I,$O46+1),"") -> 46210.223 | G46: =IFERROR(INDEX(Combined_Data!$K:$K,$O46+1),"") -> 0.1 | H46: =IFERROR(INDEX(Combined_Data!$M:$M,$O46+1),"") -> Not Captured by Scraper | I46: =IFERROR(INDEX(Combined_Data!$N:$N,$O46+1),"") -> FALSE | J46: =IFERROR(INDEX(Combined_Data!$S:$S,$O46+1),"") -> 0 | K46: =IFERROR(INDEX(Combined_Data!$AF:$AF,$O46+1),"") -> 28.6 | L46: =IFERROR(INDEX(Combined_Data!$AG:$AG,$O46+1),"") -> Uncertain | M46: =IFERROR(INDEX(Combined_Data!$AH:$AH,$O46+1),"") -> https://indeed.com/viewjob?jk=8490dafc143b3dc8 | O46: =IFERROR(_xlfn.AGGREGATE(15,6,(ROW(Combined_Data!$AI$2:$AI$3001)-1)/(Combined_Data!$AI$2:$AI$3001),12),"") -> 1246
A47: =IFERROR(INDEX(Combined_Data!$C:$C,$O47+1),"") -> Senior Snowflake Data Engineer – DBT & Power BI | B47: =IFERROR(INDEX(Combined_Data!$E:$E,$O47+1),"") -> Infosys | C47: =IFERROR(INDEX(Combined_Data!$B:$B,$O47+1),"") -> Indeed | D47: =IFERROR(INDEX(Combined_Data!$D:$D,$O47+1),"") -> Data Engineer | E47: =IFERROR(INDEX(Combined_Data!$G:$G,$O47+1),"") -> Not Specified | F47: =IFERROR(INDEX(Combined_Data!$I:$I,$O47+1),"") -> 46206.723 | G47: =IFERROR(INDEX(Combined_Data!$K:$K,$O47+1),"") -> 3.6 | H47: =IFERROR(INDEX(Combined_Data!$M:$M,$O47+1),"") -> Not Captured by Scraper | I47: =IFERROR(INDEX(Combined_Data!$N:$N,$O47+1),"") -> FALSE | J47: =IFERROR(INDEX(Combined_Data!$S:$S,$O47+1),"") -> 0 | K47: =IFERROR(INDEX(Combined_Data!$AF:$AF,$O47+1),"") -> 42.9 | L47: =IFERROR(INDEX(Combined_Data!$AG:$AG,$O47+1),"") -> Uncertain | M47: =IFERROR(INDEX(Combined_Data!$AH:$AH,$O47+1),"") -> https://indeed.com/viewjob?jk=fbd25b69e715c7e5 | O47: =IFERROR(_xlfn.AGGREGATE(15,6,(ROW(Combined_Data!$AI$2:$AI$3001)-1)/(Combined_Data!$AI$2:$AI$3001),13),"") -> 1839
A48: =IFERROR(INDEX(Combined_Data!$C:$C,$O48+1),"") -> Business analyst - Regulatory reporting | B48: =IFERROR(INDEX(Combined_Data!$E:$E,$O48+1),"") -> Infosys | C48: =IFERROR(INDEX(Combined_Data!$B:$B,$O48+1),"") -> Indeed | D48: =IFERROR(INDEX(Combined_Data!$D:$D,$O48+1),"") -> Data Analyst | E48: =IFERROR(INDEX(Combined_Data!$G:$G,$O48+1),"") -> Not Specified | F48: =IFERROR(INDEX(Combined_Data!$I:$I,$O48+1),"") -> 46205.973 | G48: =IFERROR(INDEX(Combined_Data!$K:$K,$O48+1),"") -> 4.3 | H48: =IFERROR(INDEX(Combined_Data!$M:$M,$O48+1),"") -> Not Captured by Scraper | I48: =IFERROR(INDEX(Combined_Data!$N:$N,$O48+1),"") -> FALSE | J48: =IFERROR(INDEX(Combined_Data!$S:$S,$O48+1),"") -> 0 | K48: =IFERROR(INDEX(Combined_Data!$AF:$AF,$O48+1),"") -> 42.9 | L48: =IFERROR(INDEX(Combined_Data!$AG:$AG,$O48+1),"") -> Uncertain | M48: =IFERROR(INDEX(Combined_Data!$AH:$AH,$O48+1),"") -> https://indeed.com/viewjob?jk=8291b9483fde94dc | O48: =IFERROR(_xlfn.AGGREGATE(15,6,(ROW(Combined_Data!$AI$2:$AI$3001)-1)/(Combined_Data!$AI$2:$AI$3001),14),"") -> 1930
A49: =IFERROR(INDEX(Combined_Data!$C:$C,$O49+1),"") -> Power Bi Admin | B49: =IFERROR(INDEX(Combined_Data!$E:$E,$O49+1),"") -> Infosys | C49: =IFERROR(INDEX(Combined_Data!$B:$B,$O49+1),"") -> Indeed | D49: =IFERROR(INDEX(Combined_Data!$D:$D,$O49+1),"") -> Other | E49: =IFERROR(INDEX(Combined_Data!$G:$G,$O49+1),"") -> Not Specified | F49: =IFERROR(INDEX(Combined_Data!$I:$I,$O49+1),"") -> 46205.973 | G49: =IFERROR(INDEX(Combined_Data!$K:$K,$O49+1),"") -> 4.3 | H49: =IFERROR(INDEX(Combined_Data!$M:$M,$O49+1),"") -> Not Captured by Scraper | I49: =IFERROR(INDEX(Combined_Data!$N:$N,$O49+1),"") -> FALSE | J49: =IFERROR(INDEX(Combined_Data!$S:$S,$O49+1),"") -> 0 | K49: =IFERROR(INDEX(Combined_Data!$AF:$AF,$O49+1),"") -> 28.6 | L49: =IFERROR(INDEX(Combined_Data!$AG:$AG,$O49+1),"") -> Uncertain | M49: =IFERROR(INDEX(Combined_Data!$AH:$AH,$O49+1),"") -> https://indeed.com/viewjob?jk=11262d6203dd79e8 | O49: =IFERROR(_xlfn.AGGREGATE(15,6,(ROW(Combined_Data!$AI$2:$AI$3001)-1)/(Combined_Data!$AI$2:$AI$3001),15),"") -> 1932
A50: =IFERROR(INDEX(Combined_Data!$C:$C,$O50+1),"") -> .Net Full Stack | B50: =IFERROR(INDEX(Combined_Data!$E:$E,$O50+1),"") -> Infosys | C50: =IFERROR(INDEX(Combined_Data!$B:$B,$O50+1),"") -> Indeed | D50: =IFERROR(INDEX(Combined_Data!$D:$D,$O50+1),"") -> Full Stack Engineer | E50: =IFERROR(INDEX(Combined_Data!$G:$G,$O50+1),"") -> Not Specified | F50: =IFERROR(INDEX(Combined_Data!$I:$I,$O50+1),"") -> 46209.473 | G50: =IFERROR(INDEX(Combined_Data!$K:$K,$O50+1),"") -> 0.8 | H50: =IFERROR(INDEX(Combined_Data!$M:$M,$O50+1),"") -> Not Captured by Scraper | I50: =IFERROR(INDEX(Combined_Data!$N:$N,$O50+1),"") -> FALSE | J50: =IFERROR(INDEX(Combined_Data!$S:$S,$O50+1),"") -> 0 | K50: =IFERROR(INDEX(Combined_Data!$AF:$AF,$O50+1),"") -> 42.9 | L50: =IFERROR(INDEX(Combined_Data!$AG:$AG,$O50+1),"") -> Uncertain | M50: =IFERROR(INDEX(Combined_Data!$AH:$AH,$O50+1),"") -> https://indeed.com/viewjob?jk=82530a1f7f3227d3 | O50: =IFERROR(_xlfn.AGGREGATE(15,6,(ROW(Combined_Data!$AI$2:$AI$3001)-1)/(Combined_Data!$AI$2:$AI$3001),16),"") -> 1957
A51: =IFERROR(INDEX(Combined_Data!$C:$C,$O51+1),"") -> Java Full Stack | B51: =IFERROR(INDEX(Combined_Data!$E:$E,$O51+1),"") -> Infosys | C51: =IFERROR(INDEX(Combined_Data!$B:$B,$O51+1),"") -> Indeed | D51: =IFERROR(INDEX(Combined_Data!$D:$D,$O51+1),"") -> Full Stack Engineer | E51: =IFERROR(INDEX(Combined_Data!$G:$G,$O51+1),"") -> Not Specified | F51: =IFERROR(INDEX(Combined_Data!$I:$I,$O51+1),"") -> 46209.473 | G51: =IFERROR(INDEX(Combined_Data!$K:$K,$O51+1),"") -> 0.8 | H51: =IFERROR(INDEX(Combined_Data!$M:$M,$O51+1),"") -> Not Captured by Scraper | I51: =IFERROR(INDEX(Combined_Data!$N:$N,$O51+1),"") -> FALSE | J51: =IFERROR(INDEX(Combined_Data!$S:$S,$O51+1),"") -> 0 | K51: =IFERROR(INDEX(Combined_Data!$AF:$AF,$O51+1),"") -> 42.9 | L51: =IFERROR(INDEX(Combined_Data!$AG:$AG,$O51+1),"") -> Uncertain | M51: =IFERROR(INDEX(Combined_Data!$AH:$AH,$O51+1),"") -> https://indeed.com/viewjob?jk=f40e3fa4d1983453 | O51: =IFERROR(_xlfn.AGGREGATE(15,6,(ROW(Combined_Data!$AI$2:$AI$3001)-1)/(Combined_Data!$AI$2:$AI$3001),17),"") -> 1962
A52: =IFERROR(INDEX(Combined_Data!$C:$C,$O52+1),"") -> Production Support - Java | B52: =IFERROR(INDEX(Combined_Data!$E:$E,$O52+1),"") -> Infosys | C52: =IFERROR(INDEX(Combined_Data!$B:$B,$O52+1),"") -> Indeed | D52: =IFERROR(INDEX(Combined_Data!$D:$D,$O52+1),"") -> Other | E52: =IFERROR(INDEX(Combined_Data!$G:$G,$O52+1),"") -> Not Specified | F52: =IFERROR(INDEX(Combined_Data!$I:$I,$O52+1),"") -> 46209.473 | G52: =IFERROR(INDEX(Combined_Data!$K:$K,$O52+1),"") -> 0.8 | H52: =IFERROR(INDEX(Combined_Data!$M:$M,$O52+1),"") -> Not Captured by Scraper | I52: =IFERROR(INDEX(Combined_Data!$N:$N,$O52+1),"") -> FALSE | J52: =IFERROR(INDEX(Combined_Data!$S:$S,$O52+1),"") -> 0 | K52: =IFERROR(INDEX(Combined_Data!$AF:$AF,$O52+1),"") -> 42.9 | L52: =IFERROR(INDEX(Combined_Data!$AG:$AG,$O52+1),"") -> Uncertain | M52: =IFERROR(INDEX(Combined_Data!$AH:$AH,$O52+1),"") -> https://indeed.com/viewjob?jk=da3afae1e4e530bd | O52: =IFERROR(_xlfn.AGGREGATE(15,6,(ROW(Combined_Data!$AI$2:$AI$3001)-1)/(Combined_Data!$AI$2:$AI$3001),18),"") -> 1966
A53: =IFERROR(INDEX(Combined_Data!$C:$C,$O53+1),"") -> IT Consulting | B53: =IFERROR(INDEX(Combined_Data!$E:$E,$O53+1),"") -> Infosys | C53: =IFERROR(INDEX(Combined_Data!$B:$B,$O53+1),"") -> Indeed | D53: =IFERROR(INDEX(Combined_Data!$D:$D,$O53+1),"") -> Other | E53: =IFERROR(INDEX(Combined_Data!$G:$G,$O53+1),"") -> Not Specified | F53: =IFERROR(INDEX(Combined_Data!$I:$I,$O53+1),"") -> 46209.473 | G53: =IFERROR(INDEX(Combined_Data!$K:$K,$O53+1),"") -> 0.8 | H53: =IFERROR(INDEX(Combined_Data!$M:$M,$O53+1),"") -> Not Captured by Scraper | I53: =IFERROR(INDEX(Combined_Data!$N:$N,$O53+1),"") -> FALSE | J53: =IFERROR(INDEX(Combined_Data!$S:$S,$O53+1),"") -> 0 | K53: =IFERROR(INDEX(Combined_Data!$AF:$AF,$O53+1),"") -> 42.9 | L53: =IFERROR(INDEX(Combined_Data!$AG:$AG,$O53+1),"") -> Uncertain | M53: =IFERROR(INDEX(Combined_Data!$AH:$AH,$O53+1),"") -> https://indeed.com/viewjob?jk=0f484b58a9d28673 | O53: =IFERROR(_xlfn.AGGREGATE(15,6,(ROW(Combined_Data!$AI$2:$AI$3001)-1)/(Combined_Data!$AI$2:$AI$3001),19),"") -> 1967
A54: =IFERROR(INDEX(Combined_Data!$C:$C,$O54+1),"") -> SAP ABAP Developer | B54: =IFERROR(INDEX(Combined_Data!$E:$E,$O54+1),"") -> Infosys | C54: =IFERROR(INDEX(Combined_Data!$B:$B,$O54+1),"") -> Indeed | D54: =IFERROR(INDEX(Combined_Data!$D:$D,$O54+1),"") -> Software Engineer | E54: =IFERROR(INDEX(Combined_Data!$G:$G,$O54+1),"") -> Not Specified | F54: =IFERROR(INDEX(Combined_Data!$I:$I,$O54+1),"") -> 46209.473 | G54: =IFERROR(INDEX(Combined_Data!$K:$K,$O54+1),"") -> 0.8 | H54: =IFERROR(INDEX(Combined_Data!$M:$M,$O54+1),"") -> Not Captured by Scraper | I54: =IFERROR(INDEX(Combined_Data!$N:$N,$O54+1),"") -> FALSE | J54: =IFERROR(INDEX(Combined_Data!$S:$S,$O54+1),"") -> 0 | K54: =IFERROR(INDEX(Combined_Data!$AF:$AF,$O54+1),"") -> 28.6 | L54: =IFERROR(INDEX(Combined_Data!$AG:$AG,$O54+1),"") -> Uncertain | M54: =IFERROR(INDEX(Combined_Data!$AH:$AH,$O54+1),"") -> https://indeed.com/viewjob?jk=46adcd1840e7e2eb | O54: =IFERROR(_xlfn.AGGREGATE(15,6,(ROW(Combined_Data!$AI$2:$AI$3001)-1)/(Combined_Data!$AI$2:$AI$3001),20),"") -> 1969
A55: =IFERROR(INDEX(Combined_Data!$C:$C,$O55+1),"") -> Production Support - .Net II | B55: =IFERROR(INDEX(Combined_Data!$E:$E,$O55+1),"") -> Infosys | C55: =IFERROR(INDEX(Combined_Data!$B:$B,$O55+1),"") -> Indeed | D55: =IFERROR(INDEX(Combined_Data!$D:$D,$O55+1),"") -> Other | E55: =IFERROR(INDEX(Combined_Data!$G:$G,$O55+1),"") -> Not Specified | F55: =IFERROR(INDEX(Combined_Data!$I:$I,$O55+1),"") -> 46209.473 | G55: =IFERROR(INDEX(Combined_Data!$K:$K,$O55+1),"") -> 0.8 | H55: =IFERROR(INDEX(Combined_Data!$M:$M,$O55+1),"") -> Not Captured by Scraper | I55: =IFERROR(INDEX(Combined_Data!$N:$N,$O55+1),"") -> FALSE | J55: =IFERROR(INDEX(Combined_Data!$S:$S,$O55+1),"") -> 0 | K55: =IFERROR(INDEX(Combined_Data!$AF:$AF,$O55+1),"") -> 28.6 | L55: =IFERROR(INDEX(Combined_Data!$AG:$AG,$O55+1),"") -> Uncertain | M55: =IFERROR(INDEX(Combined_Data!$AH:$AH,$O55+1),"") -> https://indeed.com/viewjob?jk=b8e1e5faf4c6aeb6 | O55: =IFERROR(_xlfn.AGGREGATE(15,6,(ROW(Combined_Data!$AI$2:$AI$3001)-1)/(Combined_Data!$AI$2:$AI$3001),21),"") -> 1973
A56: =IFERROR(INDEX(Combined_Data!$C:$C,$O56+1),"") -> Senior Systems Engineer | B56: =IFERROR(INDEX(Combined_Data!$E:$E,$O56+1),"") -> Infosys | C56: =IFERROR(INDEX(Combined_Data!$B:$B,$O56+1),"") -> Indeed | D56: =IFERROR(INDEX(Combined_Data!$D:$D,$O56+1),"") -> Other | E56: =IFERROR(INDEX(Combined_Data!$G:$G,$O56+1),"") -> Not Specified | F56: =IFERROR(INDEX(Combined_Data!$I:$I,$O56+1),"") -> 46209.473 | G56: =IFERROR(INDEX(Combined_Data!$K:$K,$O56+1),"") -> 0.8 | H56: =IFERROR(INDEX(Combined_Data!$M:$M,$O56+1),"") -> Not Captured by Scraper | I56: =IFERROR(INDEX(Combined_Data!$N:$N,$O56+1),"") -> FALSE | J56: =IFERROR(INDEX(Combined_Data!$S:$S,$O56+1),"") -> 0 | K56: =IFERROR(INDEX(Combined_Data!$AF:$AF,$O56+1),"") -> 42.9 | L56: =IFERROR(INDEX(Combined_Data!$AG:$AG,$O56+1),"") -> Uncertain | M56: =IFERROR(INDEX(Combined_Data!$AH:$AH,$O56+1),"") -> https://indeed.com/viewjob?jk=4f4f5f2faee25402 | O56: =IFERROR(_xlfn.AGGREGATE(15,6,(ROW(Combined_Data!$AI$2:$AI$3001)-1)/(Combined_Data!$AI$2:$AI$3001),22),"") -> 1977
A57: =IFERROR(INDEX(Combined_Data!$C:$C,$O57+1),"") -> Production Support - .Net | B57: =IFERROR(INDEX(Combined_Data!$E:$E,$O57+1),"") -> Infosys | C57: =IFERROR(INDEX(Combined_Data!$B:$B,$O57+1),"") -> Indeed | D57: =IFERROR(INDEX(Combined_Data!$D:$D,$O57+1),"") -> Other | E57: =IFERROR(INDEX(Combined_Data!$G:$G,$O57+1),"") -> Not Specified | F57: =IFERROR(INDEX(Combined_Data!$I:$I,$O57+1),"") -> 46209.473 | G57: =IFERROR(INDEX(Combined_Data!$K:$K,$O57+1),"") -> 0.8 | H57: =IFERROR(INDEX(Combined_Data!$M:$M,$O57+1),"") -> Not Captured by Scraper | I57: =IFERROR(INDEX(Combined_Data!$N:$N,$O57+1),"") -> FALSE | J57: =IFERROR(INDEX(Combined_Data!$S:$S,$O57+1),"") -> 0 | K57: =IFERROR(INDEX(Combined_Data!$AF:$AF,$O57+1),"") -> 28.6 | L57: =IFERROR(INDEX(Combined_Data!$AG:$AG,$O57+1),"") -> Uncertain | M57: =IFERROR(INDEX(Combined_Data!$AH:$AH,$O57+1),"") -> https://indeed.com/viewjob?jk=c16097404185408c | O57: =IFERROR(_xlfn.AGGREGATE(15,6,(ROW(Combined_Data!$AI$2:$AI$3001)-1)/(Combined_Data!$AI$2:$AI$3001),23),"") -> 1978
...

Sheet Platform_Breakdown
A1: Platform-wise Breakdown
A2: Role mix, salary levels & ghost rate — LinkedIn vs Indeed vs Glassdoor
A4: Role Distribution by Platform (listing count) | G4: Salary & Ghost Rate by Platform
A5: Role Bucket | B5: LinkedIn | C5: Indeed | D5: Glassdoor | G5: Portal | H5: Avg Annual Salary (INR est.) | I5: # Salary-Comparable | J5: Ghost Rate %
A6: Software Engineer | B6: =COUNTIFS(Combined_Data!$D$2:$D$3001,"Software Engineer",Combined_Data!$B$2:$B$3001,"LinkedIn") -> 701 | C6: =COUNTIFS(Combined_Data!$D$2:$D$3001,"Software Engineer",Combined_Data!$B$2:$B$3001,"Indeed") -> 288 | D6: =COUNTIFS(Combined_Data!$D$2:$D$3001,"Software Engineer",Combined_Data!$B$2:$B$3001,"Glassdoor") -> 209 | G6: LinkedIn | H6: =IFERROR(AVERAGEIFS(Combined_Data!$S$2:$S$3001,Combined_Data!$B$2:$B$3001,"LinkedIn",Combined_Data!$T$2:$T$3001,TRUE()),0) -> 0 | I6: =COUNTIFS(Combined_Data!$B$2:$B$3001,"LinkedIn",Combined_Data!$T$2:$T$3001,TRUE()) -> 0 | J6: =COUNTIFS(Combined_Data!$B$2:$B$3001,"LinkedIn",Combined_Data!$AG$2:$AG$3001,"Likely Ghost")/COUNTIF(Combined_Data!$B$2:$B$3001,"LinkedIn")*100 -> 7.7
A7: Other | B7: =COUNTIFS(Combined_Data!$D$2:$D$3001,"Other",Combined_Data!$B$2:$B$3001,"LinkedIn") -> 63 | C7: =COUNTIFS(Combined_Data!$D$2:$D$3001,"Other",Combined_Data!$B$2:$B$3001,"Indeed") -> 466 | D7: =COUNTIFS(Combined_Data!$D$2:$D$3001,"Other",Combined_Data!$B$2:$B$3001,"Glassdoor") -> 227 | G7: Indeed | H7: =IFERROR(AVERAGEIFS(Combined_Data!$S$2:$S$3001,Combined_Data!$B$2:$B$3001,"Indeed",Combined_Data!$T$2:$T$3001,TRUE()),0) -> 712321.28 | I7: =COUNTIFS(Combined_Data!$B$2:$B$3001,"Indeed",Combined_Data!$T$2:$T$3001,TRUE()) -> 148 | J7: =COUNTIFS(Combined_Data!$B$2:$B$3001,"Indeed",Combined_Data!$AG$2:$AG$3001,"Likely Ghost")/COUNTIF(Combined_Data!$B$2:$B$3001,"Indeed")*100 -> 4.4
A8: Data Analyst | B8: =COUNTIFS(Combined_Data!$D$2:$D$3001,"Data Analyst",Combined_Data!$B$2:$B$3001,"LinkedIn") -> 0 | C8: =COUNTIFS(Combined_Data!$D$2:$D$3001,"Data Analyst",Combined_Data!$B$2:$B$3001,"Indeed") -> 93 | D8: =COUNTIFS(Combined_Data!$D$2:$D$3001,"Data Analyst",Combined_Data!$B$2:$B$3001,"Glassdoor") -> 178 | G8: Glassdoor | H8: =IFERROR(AVERAGEIFS(Combined_Data!$S$2:$S$3001,Combined_Data!$B$2:$B$3001,"Glassdoor",Combined_Data!$T$2:$T$3001,TRUE()),0) -> 608706.69 | I8: =COUNTIFS(Combined_Data!$B$2:$B$3001,"Glassdoor",Combined_Data!$T$2:$T$3001,TRUE()) -> 451 | J8: =COUNTIFS(Combined_Data!$B$2:$B$3001,"Glassdoor",Combined_Data!$AG$2:$AG$3001,"Likely Ghost")/COUNTIF(Combined_Data!$B$2:$B$3001,"Glassdoor")*100 -> 2.5
A9: ML Engineer | B9: =COUNTIFS(Combined_Data!$D$2:$D$3001,"ML Engineer",Combined_Data!$B$2:$B$3001,"LinkedIn") -> 1 | C9: =COUNTIFS(Combined_Data!$D$2:$D$3001,"ML Engineer",Combined_Data!$B$2:$B$3001,"Indeed") -> 14 | D9: =COUNTIFS(Combined_Data!$D$2:$D$3001,"ML Engineer",Combined_Data!$B$2:$B$3001,"Glassdoor") -> 189
A10: Frontend Engineer | B10: =COUNTIFS(Combined_Data!$D$2:$D$3001,"Frontend Engineer",Combined_Data!$B$2:$B$3001,"LinkedIn") -> 30 | C10: =COUNTIFS(Combined_Data!$D$2:$D$3001,"Frontend Engineer",Combined_Data!$B$2:$B$3001,"Indeed") -> 5 | D10: =COUNTIFS(Combined_Data!$D$2:$D$3001,"Frontend Engineer",Combined_Data!$B$2:$B$3001,"Glassdoor") -> 119
A11: Full Stack Engineer | B11: =COUNTIFS(Combined_Data!$D$2:$D$3001,"Full Stack Engineer",Combined_Data!$B$2:$B$3001,"LinkedIn") -> 79 | C11: =COUNTIFS(Combined_Data!$D$2:$D$3001,"Full Stack Engineer",Combined_Data!$B$2:$B$3001,"Indeed") -> 56 | D11: =COUNTIFS(Combined_Data!$D$2:$D$3001,"Full Stack Engineer",Combined_Data!$B$2:$B$3001,"Glassdoor") -> 14
A12: Backend Engineer | B12: =COUNTIFS(Combined_Data!$D$2:$D$3001,"Backend Engineer",Combined_Data!$B$2:$B$3001,"LinkedIn") -> 121 | C12: =COUNTIFS(Combined_Data!$D$2:$D$3001,"Backend Engineer",Combined_Data!$B$2:$B$3001,"Indeed") -> 16 | D12: =COUNTIFS(Combined_Data!$D$2:$D$3001,"Backend Engineer",Combined_Data!$B$2:$B$3001,"Glassdoor") -> 6
A13: Data Scientist | B13: =COUNTIFS(Combined_Data!$D$2:$D$3001,"Data Scientist",Combined_Data!$B$2:$B$3001,"LinkedIn") -> 0 | C13: =COUNTIFS(Combined_Data!$D$2:$D$3001,"Data Scientist",Combined_Data!$B$2:$B$3001,"Indeed") -> 9 | D13: =COUNTIFS(Combined_Data!$D$2:$D$3001,"Data Scientist",Combined_Data!$B$2:$B$3001,"Glassdoor") -> 36
A14: Data Engineer | B14: =COUNTIFS(Combined_Data!$D$2:$D$3001,"Data Engineer",Combined_Data!$B$2:$B$3001,"LinkedIn") -> 0 | C14: =COUNTIFS(Combined_Data!$D$2:$D$3001,"Data Engineer",Combined_Data!$B$2:$B$3001,"Indeed") -> 14 | D14: =COUNTIFS(Combined_Data!$D$2:$D$3001,"Data Engineer",Combined_Data!$B$2:$B$3001,"Glassdoor") -> 22
A15: DevOps Engineer | B15: =COUNTIFS(Combined_Data!$D$2:$D$3001,"DevOps Engineer",Combined_Data!$B$2:$B$3001,"LinkedIn") -> 0 | C15: =COUNTIFS(Combined_Data!$D$2:$D$3001,"DevOps Engineer",Combined_Data!$B$2:$B$3001,"Indeed") -> 24 | D15: =COUNTIFS(Combined_Data!$D$2:$D$3001,"DevOps Engineer",Combined_Data!$B$2:$B$3001,"Glassdoor") -> 0
A16: QA/Test Engineer | B16: =COUNTIFS(Combined_Data!$D$2:$D$3001,"QA/Test Engineer",Combined_Data!$B$2:$B$3001,"LinkedIn") -> 5 | C16: =COUNTIFS(Combined_Data!$D$2:$D$3001,"QA/Test Engineer",Combined_Data!$B$2:$B$3001,"Indeed") -> 9 | D16: =COUNTIFS(Combined_Data!$D$2:$D$3001,"QA/Test Engineer",Combined_Data!$B$2:$B$3001,"Glassdoor") -> 0
A17: Product Manager | B17: =COUNTIFS(Combined_Data!$D$2:$D$3001,"Product Manager",Combined_Data!$B$2:$B$3001,"LinkedIn") -> 0 | C17: =COUNTIFS(Combined_Data!$D$2:$D$3001,"Product Manager",Combined_Data!$B$2:$B$3001,"Indeed") -> 6 | D17: =COUNTIFS(Combined_Data!$D$2:$D$3001,"Product Manager",Combined_Data!$B$2:$B$3001,"Glassdoor") -> 0

Sheet Top_Companies
A1: Top Companies & Employer Trust Score
A2: Top 20 employers by posting volume (across all 3 platforms, names as scraped — see ReadMe on entity resolution)
A4: Company Name | B4: Total Postings | C4: Likely Ghost | D4: Ghost Rate % | E4: Avg Ghost Score % | F4: Employer Trust Score
A5: Accenture in India | B5: =COUNTIF(Combined_Data!$E$2:$E$3001,"Accenture in India") -> 429 | C5: =COUNTIFS(Combined_Data!$E$2:$E$3001,"Accenture in India",Combined_Data!$AG$2:$AG$3001,"Likely Ghost") -> 77 | D5: =C5/B5*100 -> 17.948718 | E5: =AVERAGEIF(Combined_Data!$E$2:$E$3001,"Accenture in India",Combined_Data!$AF$2:$AF$3001) -> 45.448718 | F5: =100-E5 -> 54.551282
A6: Wipro | B6: =COUNTIF(Combined_Data!$E$2:$E$3001,"Wipro") -> 81 | C6: =COUNTIFS(Combined_Data!$E$2:$E$3001,"Wipro",Combined_Data!$AG$2:$AG$3001,"Likely Ghost") -> 9 | D6: =C6/B6*100 -> 11.111111 | E6: =AVERAGEIF(Combined_Data!$E$2:$E$3001,"Wipro",Combined_Data!$AF$2:$AF$3001) -> 44.477778 | F6: =100-E6 -> 55.522222
A7: Accenture | B7: =COUNTIF(Combined_Data!$E$2:$E$3001,"Accenture") -> 64 | C7: =COUNTIFS(Combined_Data!$E$2:$E$3001,"Accenture",Combined_Data!$AG$2:$AG$3001,"Likely Ghost") -> 23 | D7: =C7/B7*100 -> 35.9375 | E7: =AVERAGEIF(Combined_Data!$E$2:$E$3001,"Accenture",Combined_Data!$AF$2:$AF$3001) -> 48.003125 | F7: =100-E7 -> 51.996875
A8: Capgemini | B8: =COUNTIF(Combined_Data!$E$2:$E$3001,"Capgemini") -> 50 | C8: =COUNTIFS(Combined_Data!$E$2:$E$3001,"Capgemini",Combined_Data!$AG$2:$AG$3001,"Likely Ghost") -> 0 | D8: =C8/B8*100 -> 0 | E8: =AVERAGEIF(Combined_Data!$E$2:$E$3001,"Capgemini",Combined_Data!$AF$2:$AF$3001) -> 28.028 | F8: =100-E8 -> 71.972
A9: Calpion | B9: =COUNTIF(Combined_Data!$E$2:$E$3001,"Calpion") -> 42 | C9: =COUNTIFS(Combined_Data!$E$2:$E$3001,"Calpion",Combined_Data!$AG$2:$AG$3001,"Likely Ghost") -> 0 | D9: =C9/B9*100 -> 0 | E9: =AVERAGEIF(Combined_Data!$E$2:$E$3001,"Calpion",Combined_Data!$AF$2:$AF$3001) -> 14.3 | F9: =100-E9 -> 85.7
A10: Amazon.com | B10: =COUNTIF(Combined_Data!$E$2:$E$3001,"Amazon.com") -> 33 | C10: =COUNTIFS(Combined_Data!$E$2:$E$3001,"Amazon.com",Combined_Data!$AG$2:$AG$3001,"Likely Ghost") -> 0 | D10: =C10/B10*100 -> 0 | E10: =AVERAGEIF(Combined_Data!$E$2:$E$3001,"Amazon.com",Combined_Data!$AF$2:$AF$3001) -> 16.9 | F10: =100-E10 -> 83.1
A11: Infosys | B11: =COUNTIF(Combined_Data!$E$2:$E$3001,"Infosys") -> 24 | C11: =COUNTIFS(Combined_Data!$E$2:$E$3001,"Infosys",Combined_Data!$AG$2:$AG$3001,"Likely Ghost") -> 0 | D11: =C11/B11*100 -> 0 | E11: =AVERAGEIF(Combined_Data!$E$2:$E$3001,"Infosys",Combined_Data!$AF$2:$AF$3001) -> 29.195833 | F11: =100-E11 -> 70.804167
A12: U.S. Bank | B12: =COUNTIF(Combined_Data!$E$2:$E$3001,"U.S. Bank") -> 18 | C12: =COUNTIFS(Combined_Data!$E$2:$E$3001,"U.S. Bank",Combined_Data!$AG$2:$AG$3001,"Likely Ghost") -> 0 | D12: =C12/B12*100 -> 0 | E12: =AVERAGEIF(Combined_Data!$E$2:$E$3001,"U.S. Bank",Combined_Data!$AF$2:$AF$3001) -> 14.3 | F12: =100-E12 -> 85.7
A13: Citi | B13: =COUNTIF(Combined_Data!$E$2:$E$3001,"Citi") -> 18 | C13: =COUNTIFS(Combined_Data!$E$2:$E$3001,"Citi",Combined_Data!$AG$2:$AG$3001,"Likely Ghost") -> 0 | D13: =C13/B13*100 -> 0 | E13: =AVERAGEIF(Combined_Data!$E$2:$E$3001,"Citi",Combined_Data!$AF$2:$AF$3001) -> 19.066667 | F13: =100-E13 -> 80.933333
A14: Citigroup Inc. | B14: =COUNTIF(Combined_Data!$E$2:$E$3001,"Citigroup Inc.") -> 18 | C14: =COUNTIFS(Combined_Data!$E$2:$E$3001,"Citigroup Inc.",Combined_Data!$AG$2:$AG$3001,"Likely Ghost") -> 1 | D14: =C14/B14*100 -> 5.5555556 | E14: =AVERAGEIF(Combined_Data!$E$2:$E$3001,"Citigroup Inc.",Combined_Data!$AF$2:$AF$3001) -> 37.333333 | F14: =100-E14 -> 62.666667
A15: Amazon.com, Inc. | B15: =COUNTIF(Combined_Data!$E$2:$E$3001,"Amazon.com, Inc.") -> 17 | C15: =COUNTIFS(Combined_Data!$E$2:$E$3001,"Amazon.com, Inc.",Combined_Data!$AG$2:$AG$3001,"Likely Ghost") -> 0 | D15: =C15/B15*100 -> 0 | E15: =AVERAGEIF(Combined_Data!$E$2:$E$3001,"Amazon.com, Inc.",Combined_Data!$AF$2:$AF$3001) -> 37.011765 | F15: =100-E15 -> 62.988235
A16: Accenture Ltd | B16: =COUNTIF(Combined_Data!$E$2:$E$3001,"Accenture Ltd") -> 17 | C16: =COUNTIFS(Combined_Data!$E$2:$E$3001,"Accenture Ltd",Combined_Data!$AG$2:$AG$3001,"Likely Ghost") -> 4 | D16: =C16/B16*100 -> 23.529412 | E16: =AVERAGEIF(Combined_Data!$E$2:$E$3001,"Accenture Ltd",Combined_Data!$AF$2:$AF$3001) -> 43.717647 | F16: =100-E16 -> 56.282353
A17: Deloitte | B17: =COUNTIF(Combined_Data!$E$2:$E$3001,"Deloitte") -> 16 | C17: =COUNTIFS(Combined_Data!$E$2:$E$3001,"Deloitte",Combined_Data!$AG$2:$AG$3001,"Likely Ghost") -> 0 | D17: =C17/B17*100 -> 0 | E17: =AVERAGEIF(Combined_Data!$E$2:$E$3001,"Deloitte",Combined_Data!$AF$2:$AF$3001) -> 25.91875 | F17: =100-E17 -> 74.08125
A18: Optum, Inc. | B18: =COUNTIF(Combined_Data!$E$2:$E$3001,"Optum, Inc.") -> 16 | C18: =COUNTIFS(Combined_Data!$E$2:$E$3001,"Optum, Inc.",Combined_Data!$AG$2:$AG$3001,"Likely Ghost") -> 0 | D18: =C18/B18*100 -> 0 | E18: =AVERAGEIF(Combined_Data!$E$2:$E$3001,"Optum, Inc.",Combined_Data!$AF$2:$AF$3001) -> 39.325 | F18: =100-E18 -> 60.675
A19: Amazon | B19: =COUNTIF(Combined_Data!$E$2:$E$3001,"Amazon") -> 16 | C19: =COUNTIFS(Combined_Data!$E$2:$E$3001,"Amazon",Combined_Data!$AG$2:$AG$3001,"Likely Ghost") -> 0 | D19: =C19/B19*100 -> 0 | E19: =AVERAGEIF(Combined_Data!$E$2:$E$3001,"Amazon",Combined_Data!$AF$2:$AF$3001) -> 16.0875 | F19: =100-E19 -> 83.9125
A20: JPMorganChase | B20: =COUNTIF(Combined_Data!$E$2:$E$3001,"JPMorganChase") -> 15 | C20: =COUNTIFS(Combined_Data!$E$2:$E$3001,"JPMorganChase",Combined_Data!$AG$2:$AG$3001,"Likely Ghost") -> 0 | D20: =C20/B20*100 -> 0 | E20: =AVERAGEIF(Combined_Data!$E$2:$E$3001,"JPMorganChase",Combined_Data!$AF$2:$AF$3001) -> 20.973333 | F20: =100-E20 -> 79.026667
A21: ExlService Holdings, Inc. | B21: =COUNTIF(Combined_Data!$E$2:$E$3001,"ExlService Holdings, Inc.") -> 15 | C21: =COUNTIFS(Combined_Data!$E$2:$E$3001,"ExlService Holdings, Inc.",Combined_Data!$AG$2:$AG$3001,"Likely Ghost") -> 1 | D21: =C21/B21*100 -> 6.6666667 | E21: =AVERAGEIF(Combined_Data!$E$2:$E$3001,"ExlService Holdings, Inc.",Combined_Data!$AF$2:$AF$3001) -> 40.033333 | F21: =100-E21 -> 59.966667
A22: Persistent Systems | B22: =COUNTIF(Combined_Data!$E$2:$E$3001,"Persistent Systems") -> 15 | C22: =COUNTIFS(Combined_Data!$E$2:$E$3001,"Persistent Systems",Combined_Data!$AG$2:$AG$3001,"Likely Ghost") -> 0 | D22: =C22/B22*100 -> 0 | E22: =AVERAGEIF(Combined_Data!$E$2:$E$3001,"Persistent Systems",Combined_Data!$AF$2:$AF$3001) -> 19.066667 | F22: =100-E22 -> 80.933333
A23: Cisco | B23: =COUNTIF(Combined_Data!$E$2:$E$3001,"Cisco") -> 14 | C23: =COUNTIFS(Combined_Data!$E$2:$E$3001,"Cisco",Combined_Data!$AG$2:$AG$3001,"Likely Ghost") -> 0 | D23: =C23/B23*100 -> 0 | E23: =AVERAGEIF(Combined_Data!$E$2:$E$3001,"Cisco",Combined_Data!$AF$2:$AF$3001) -> 15.321429 | F23: =100-E23 -> 84.678571
A24: Husky Injection Molding | B24: =COUNTIF(Combined_Data!$E$2:$E$3001,"Husky Injection Molding") -> 14 | C24: =COUNTIFS(Combined_Data!$E$2:$E$3001,"Husky Injection Molding",Combined_Data!$AG$2:$AG$3001,"Likely Ghost") -> 0 | D24: =C24/B24*100 -> 0 | E24: =AVERAGEIF(Combined_Data!$E$2:$E$3001,"Husky Injection Molding",Combined_Data!$AF$2:$AF$3001) -> 14.3 | F24: =100-E24 -> 85.7

Sheet Role_Analysis
A1: Role-wise Analysis
A2: Data Analyst vs Software Engineer vs ML Engineer, etc. — ghost rate & salary by role
A4: Role Bucket | B4: Total Postings | C4: Likely Ghost | D4: Ghost Rate % | E4: Avg Days Live | F4: Avg Annual Salary (INR est.)
A5: Software Engineer | B5: =COUNTIF(Combined_Data!$D$2:$D$3001,"Software Engineer") -> 1198 | C5: =COUNTIFS(Combined_Data!$D$2:$D$3001,"Software Engineer",Combined_Data!$AG$2:$AG$3001,"Likely Ghost") -> 93 | D5: =C5/B5*100 -> 7.7629382 | E5: =AVERAGEIF(Combined_Data!$D$2:$D$3001,"Software Engineer",Combined_Data!$K$2:$K$3001) -> 32.650501 | F5: =IFERROR(AVERAGEIFS(Combined_Data!$S$2:$S$3001,Combined_Data!$D$2:$D$3001,"Software Engineer",Combined_Data!$T$2:$T$3001,TRUE()),0) -> 582718.11
A6: Other | B6: =COUNTIF(Combined_Data!$D$2:$D$3001,"Other") -> 756 | C6: =COUNTIFS(Combined_Data!$D$2:$D$3001,"Other",Combined_Data!$AG$2:$AG$3001,"Likely Ghost") -> 26 | D6: =C6/B6*100 -> 3.4391534 | E6: =AVERAGEIF(Combined_Data!$D$2:$D$3001,"Other",Combined_Data!$K$2:$K$3001) -> 16.557937 | F6: =IFERROR(AVERAGEIFS(Combined_Data!$S$2:$S$3001,Combined_Data!$D$2:$D$3001,"Other",Combined_Data!$T$2:$T$3001,TRUE()),0) -> 613551.15
A7: Data Analyst | B7: =COUNTIF(Combined_Data!$D$2:$D$3001,"Data Analyst") -> 271 | C7: =COUNTIFS(Combined_Data!$D$2:$D$3001,"Data Analyst",Combined_Data!$AG$2:$AG$3001,"Likely Ghost") -> 10 | D7: =C7/B7*100 -> 3.6900369 | E7: =AVERAGEIF(Combined_Data!$D$2:$D$3001,"Data Analyst",Combined_Data!$K$2:$K$3001) -> 29.852399 | F7: =IFERROR(AVERAGEIFS(Combined_Data!$S$2:$S$3001,Combined_Data!$D$2:$D$3001,"Data Analyst",Combined_Data!$T$2:$T$3001,TRUE()),0) -> 563160.42
A8: ML Engineer | B8: =COUNTIF(Combined_Data!$D$2:$D$3001,"ML Engineer") -> 204 | C8: =COUNTIFS(Combined_Data!$D$2:$D$3001,"ML Engineer",Combined_Data!$AG$2:$AG$3001,"Likely Ghost") -> 12 | D8: =C8/B8*100 -> 5.8823529 | E8: =AVERAGEIF(Combined_Data!$D$2:$D$3001,"ML Engineer",Combined_Data!$K$2:$K$3001) -> 53.192647 | F8: =IFERROR(AVERAGEIFS(Combined_Data!$S$2:$S$3001,Combined_Data!$D$2:$D$3001,"ML Engineer",Combined_Data!$T$2:$T$3001,TRUE()),0) -> 638042.2
A9: Frontend Engineer | B9: =COUNTIF(Combined_Data!$D$2:$D$3001,"Frontend Engineer") -> 154 | C9: =COUNTIFS(Combined_Data!$D$2:$D$3001,"Frontend Engineer",Combined_Data!$AG$2:$AG$3001,"Likely Ghost") -> 3 | D9: =C9/B9*100 -> 1.9480519 | E9: =AVERAGEIF(Combined_Data!$D$2:$D$3001,"Frontend Engineer",Combined_Data!$K$2:$K$3001) -> 92.096753 | F9: =IFERROR(AVERAGEIFS(Combined_Data!$S$2:$S$3001,Combined_Data!$D$2:$D$3001,"Frontend Engineer",Combined_Data!$T$2:$T$3001,TRUE()),0) -> 633805.33
A10: Full Stack Engineer | B10: =COUNTIF(Combined_Data!$D$2:$D$3001,"Full Stack Engineer") -> 149 | C10: =COUNTIFS(Combined_Data!$D$2:$D$3001,"Full Stack Engineer",Combined_Data!$AG$2:$AG$3001,"Likely Ghost") -> 1 | D10: =C10/B10*100 -> 0.67114094 | E10: =AVERAGEIF(Combined_Data!$D$2:$D$3001,"Full Stack Engineer",Combined_Data!$K$2:$K$3001) -> 28.612081 | F10: =IFERROR(AVERAGEIFS(Combined_Data!$S$2:$S$3001,Combined_Data!$D$2:$D$3001,"Full Stack Engineer",Combined_Data!$T$2:$T$3001,TRUE()),0) -> 1387600.2
A11: Backend Engineer | B11: =COUNTIF(Combined_Data!$D$2:$D$3001,"Backend Engineer") -> 143 | C11: =COUNTIFS(Combined_Data!$D$2:$D$3001,"Backend Engineer",Combined_Data!$AG$2:$AG$3001,"Likely Ghost") -> 0 | D11: =C11/B11*100 -> 0 | E11: =AVERAGEIF(Combined_Data!$D$2:$D$3001,"Backend Engineer",Combined_Data!$K$2:$K$3001) -> 71.73986 | F11: =IFERROR(AVERAGEIFS(Combined_Data!$S$2:$S$3001,Combined_Data!$D$2:$D$3001,"Backend Engineer",Combined_Data!$T$2:$T$3001,TRUE()),0) -> 929815.25
A12: Data Scientist | B12: =COUNTIF(Combined_Data!$D$2:$D$3001,"Data Scientist") -> 45 | C12: =COUNTIFS(Combined_Data!$D$2:$D$3001,"Data Scientist",Combined_Data!$AG$2:$AG$3001,"Likely Ghost") -> 1 | D12: =C12/B12*100 -> 2.2222222 | E12: =AVERAGEIF(Combined_Data!$D$2:$D$3001,"Data Scientist",Combined_Data!$K$2:$K$3001) -> 52.62 | F12: =IFERROR(AVERAGEIFS(Combined_Data!$S$2:$S$3001,Combined_Data!$D$2:$D$3001,"Data Scientist",Combined_Data!$T$2:$T$3001,TRUE()),0) -> 596326.92
A13: Data Engineer | B13: =COUNTIF(Combined_Data!$D$2:$D$3001,"Data Engineer") -> 36 | C13: =COUNTIFS(Combined_Data!$D$2:$D$3001,"Data Engineer",Combined_Data!$AG$2:$AG$3001,"Likely Ghost") -> 0 | D13: =C13/B13*100 -> 0 | E13: =AVERAGEIF(Combined_Data!$D$2:$D$3001,"Data Engineer",Combined_Data!$K$2:$K$3001) -> 26.308333 | F13: =IFERROR(AVERAGEIFS(Combined_Data!$S$2:$S$3001,Combined_Data!$D$2:$D$3001,"Data Engineer",Combined_Data!$T$2:$T$3001,TRUE()),0) -> 906050
A14: DevOps Engineer | B14: =COUNTIF(Combined_Data!$D$2:$D$3001,"DevOps Engineer") -> 24 | C14: =COUNTIFS(Combined_Data!$D$2:$D$3001,"DevOps Engineer",Combined_Data!$AG$2:$AG$3001,"Likely Ghost") -> 0 | D14: =C14/B14*100 -> 0 | E14: =AVERAGEIF(Combined_Data!$D$2:$D$3001,"DevOps Engineer",Combined_Data!$K$2:$K$3001) -> 0.22083333 | F14: =IFERROR(AVERAGEIFS(Combined_Data!$S$2:$S$3001,Combined_Data!$D$2:$D$3001,"DevOps Engineer",Combined_Data!$T$2:$T$3001,TRUE()),0) -> 787010.67
A15: QA/Test Engineer | B15: =COUNTIF(Combined_Data!$D$2:$D$3001,"QA/Test Engineer") -> 14 | C15: =COUNTIFS(Combined_Data!$D$2:$D$3001,"QA/Test Engineer",Combined_Data!$AG$2:$AG$3001,"Likely Ghost") -> 0 | D15: =C15/B15*100 -> 0 | E15: =AVERAGEIF(Combined_Data!$D$2:$D$3001,"QA/Test Engineer",Combined_Data!$K$2:$K$3001) -> 16.135714 | F15: =IFERROR(AVERAGEIFS(Combined_Data!$S$2:$S$3001,Combined_Data!$D$2:$D$3001,"QA/Test Engineer",Combined_Data!$T$2:$T$3001,TRUE()),0) -> 919910
A16: Product Manager | B16: =COUNTIF(Combined_Data!$D$2:$D$3001,"Product Manager") -> 6 | C16: =COUNTIFS(Combined_Data!$D$2:$D$3001,"Product Manager",Combined_Data!$AG$2:$AG$3001,"Likely Ghost") -> 0 | D16: =C16/B16*100 -> 0 | E16: =AVERAGEIF(Combined_Data!$D$2:$D$3001,"Product Manager",Combined_Data!$K$2:$K$3001) -> 0.93333333 | F16: =IFERROR(AVERAGEIFS(Combined_Data!$S$2:$S$3001,Combined_Data!$D$2:$D$3001,"Product Manager",Combined_Data!$T$2:$T$3001,TRUE()),0) -> 0

Sheet City_Analysis
A1: City / Location Analysis
A2: Ghost rate & posting volume by city (top 15 cities by listing count, "Not Specified" = location omitted by scraper/employer)
A4: City | B4: Total Postings | C4: Likely Ghost | D4: Ghost Rate % | E4: Avg Days Live | F4: Avg Ghost Score %
A5: Not Specified | B5: =COUNTIF(Combined_Data!$G$2:$G$3001,"Not Specified") -> 1550 | C5: =COUNTIFS(Combined_Data!$G$2:$G$3001,"Not Specified",Combined_Data!$AG$2:$AG$3001,"Likely Ghost") -> 55 | D5: =IFERROR(C5/B5*100,0) -> 3.5483871 | E5: =IFERROR(AVERAGEIF(Combined_Data!$G$2:$G$3001,"Not Specified",Combined_Data!$K$2:$K$3001),0) -> 22.924774 | F5: =IFERROR(AVERAGEIF(Combined_Data!$G$2:$G$3001,"Not Specified",Combined_Data!$AF$2:$AF$3001),0) -> 24.343355
A6: Bengaluru | B6: =COUNTIF(Combined_Data!$G$2:$G$3001,"Bengaluru") -> 359 | C6: =COUNTIFS(Combined_Data!$G$2:$G$3001,"Bengaluru",Combined_Data!$AG$2:$AG$3001,"Likely Ghost") -> 16 | D6: =IFERROR(C6/B6*100,0) -> 4.4568245 | E6: =IFERROR(AVERAGEIF(Combined_Data!$G$2:$G$3001,"Bengaluru",Combined_Data!$K$2:$K$3001),0) -> 40.203343 | F6: =IFERROR(AVERAGEIF(Combined_Data!$G$2:$G$3001,"Bengaluru",Combined_Data!$AF$2:$AF$3001),0) -> 24.612256
A7: Chennai | B7: =COUNTIF(Combined_Data!$G$2:$G$3001,"Chennai") -> 165 | C7: =COUNTIFS(Combined_Data!$G$2:$G$3001,"Chennai",Combined_Data!$AG$2:$AG$3001,"Likely Ghost") -> 8 | D7: =IFERROR(C7/B7*100,0) -> 4.8484848 | E7: =IFERROR(AVERAGEIF(Combined_Data!$G$2:$G$3001,"Chennai",Combined_Data!$K$2:$K$3001),0) -> 44.478788 | F7: =IFERROR(AVERAGEIF(Combined_Data!$G$2:$G$3001,"Chennai",Combined_Data!$AF$2:$AF$3001),0) -> 27.728485
A8: Pune Division | B8: =COUNTIF(Combined_Data!$G$2:$G$3001,"Pune Division") -> 78 | C8: =COUNTIFS(Combined_Data!$G$2:$G$3001,"Pune Division",Combined_Data!$AG$2:$AG$3001,"Likely Ghost") -> 5 | D8: =IFERROR(C8/B8*100,0) -> 6.4102564 | E8: =IFERROR(AVERAGEIF(Combined_Data!$G$2:$G$3001,"Pune Division",Combined_Data!$K$2:$K$3001),0) -> 30.910256 | F8: =IFERROR(AVERAGEIF(Combined_Data!$G$2:$G$3001,"Pune Division",Combined_Data!$AF$2:$AF$3001),0) -> 32.44359
A9: Hyderabad | B9: =COUNTIF(Combined_Data!$G$2:$G$3001,"Hyderabad") -> 75 | C9: =COUNTIFS(Combined_Data!$G$2:$G$3001,"Hyderabad",Combined_Data!$AG$2:$AG$3001,"Likely Ghost") -> 4 | D9: =IFERROR(C9/B9*100,0) -> 5.3333333 | E9: =IFERROR(AVERAGEIF(Combined_Data!$G$2:$G$3001,"Hyderabad",Combined_Data!$K$2:$K$3001),0) -> 30.306667 | F9: =IFERROR(AVERAGEIF(Combined_Data!$G$2:$G$3001,"Hyderabad",Combined_Data!$AF$2:$AF$3001),0) -> 34.696
A10: Mumbai Metropolitan Region | B10: =COUNTIF(Combined_Data!$G$2:$G$3001,"Mumbai Metropolitan Region") -> 54 | C10: =COUNTIFS(Combined_Data!$G$2:$G$3001,"Mumbai Metropolitan Region",Combined_Data!$AG$2:$AG$3001,"Likely Ghost") -> 6 | D10: =IFERROR(C10/B10*100,0) -> 11.111111 | E10: =IFERROR(AVERAGEIF(Combined_Data!$G$2:$G$3001,"Mumbai Metropolitan Region",Combined_Data!$K$2:$K$3001),0) -> 68.518519 | F10: =IFERROR(AVERAGEIF(Combined_Data!$G$2:$G$3001,"Mumbai Metropolitan Region",Combined_Data!$AF$2:$AF$3001),0) -> 37.592593
A11: Mumbai | B11: =COUNTIF(Combined_Data!$G$2:$G$3001,"Mumbai") -> 51 | C11: =COUNTIFS(Combined_Data!$G$2:$G$3001,"Mumbai",Combined_Data!$AG$2:$AG$3001,"Likely Ghost") -> 10 | D11: =IFERROR(C11/B11*100,0) -> 19.607843 | E11: =IFERROR(AVERAGEIF(Combined_Data!$G$2:$G$3001,"Mumbai",Combined_Data!$K$2:$K$3001),0) -> 50.882353 | F11: =IFERROR(AVERAGEIF(Combined_Data!$G$2:$G$3001,"Mumbai",Combined_Data!$AF$2:$AF$3001),0) -> 30.823529
A12: Coimbatore | B12: =COUNTIF(Combined_Data!$G$2:$G$3001,"Coimbatore") -> 50 | C12: =COUNTIFS(Combined_Data!$G$2:$G$3001,"Coimbatore",Combined_Data!$AG$2:$AG$3001,"Likely Ghost") -> 7 | D12: =IFERROR(C12/B12*100,0) -> 14 | E12: =IFERROR(AVERAGEIF(Combined_Data!$G$2:$G$3001,"Coimbatore",Combined_Data!$K$2:$K$3001),0) -> 29.02 | F12: =IFERROR(AVERAGEIF(Combined_Data!$G$2:$G$3001,"Coimbatore",Combined_Data!$AF$2:$AF$3001),0) -> 37.166
A13: Jaipur | B13: =COUNTIF(Combined_Data!$G$2:$G$3001,"Jaipur") -> 47 | C13: =COUNTIFS(Combined_Data!$G$2:$G$3001,"Jaipur",Combined_Data!$AG$2:$AG$3001,"Likely Ghost") -> 4 | D13: =IFERROR(C13/B13*100,0) -> 8.5106383 | E13: =IFERROR(AVERAGEIF(Combined_Data!$G$2:$G$3001,"Jaipur",Combined_Data!$K$2:$K$3001),0) -> 28.148936 | F13: =IFERROR(AVERAGEIF(Combined_Data!$G$2:$G$3001,"Jaipur",Combined_Data!$AF$2:$AF$3001),0) -> 41.674468
A14: Gurugram | B14: =COUNTIF(Combined_Data!$G$2:$G$3001,"Gurugram") -> 46 | C14: =COUNTIFS(Combined_Data!$G$2:$G$3001,"Gurugram",Combined_Data!$AG$2:$AG$3001,"Likely Ghost") -> 3 | D14: =IFERROR(C14/B14*100,0) -> 6.5217391 | E14: =IFERROR(AVERAGEIF(Combined_Data!$G$2:$G$3001,"Gurugram",Combined_Data!$K$2:$K$3001),0) -> 25.652174 | F14: =IFERROR(AVERAGEIF(Combined_Data!$G$2:$G$3001,"Gurugram",Combined_Data!$AF$2:$AF$3001),0) -> 33.878261
A15: Pune | B15: =COUNTIF(Combined_Data!$G$2:$G$3001,"Pune") -> 46 | C15: =COUNTIFS(Combined_Data!$G$2:$G$3001,"Pune",Combined_Data!$AG$2:$AG$3001,"Likely Ghost") -> 0 | D15: =IFERROR(C15/B15*100,0) -> 0 | E15: =IFERROR(AVERAGEIF(Combined_Data!$G$2:$G$3001,"Pune",Combined_Data!$K$2:$K$3001),0) -> 62.673913 | F15: =IFERROR(AVERAGEIF(Combined_Data!$G$2:$G$3001,"Pune",Combined_Data!$AF$2:$AF$3001),0) -> 15.232609
A16: Gurgaon | B16: =COUNTIF(Combined_Data!$G$2:$G$3001,"Gurgaon") -> 33 | C16: =COUNTIFS(Combined_Data!$G$2:$G$3001,"Gurgaon",Combined_Data!$AG$2:$AG$3001,"Likely Ghost") -> 0 | D16: =IFERROR(C16/B16*100,0) -> 0 | E16: =IFERROR(AVERAGEIF(Combined_Data!$G$2:$G$3001,"Gurgaon",Combined_Data!$K$2:$K$3001),0) -> 58.909091 | F16: =IFERROR(AVERAGEIF(Combined_Data!$G$2:$G$3001,"Gurgaon",Combined_Data!$AF$2:$AF$3001),0) -> 21.233333
A17: Remote | B17: =COUNTIF(Combined_Data!$G$2:$G$3001,"Remote") -> 32 | C17: =COUNTIFS(Combined_Data!$G$2:$G$3001,"Remote",Combined_Data!$AG$2:$AG$3001,"Likely Ghost") -> 3 | D17: =IFERROR(C17/B17*100,0) -> 9.375 | E17: =IFERROR(AVERAGEIF(Combined_Data!$G$2:$G$3001,"Remote",Combined_Data!$K$2:$K$3001),0) -> 0.646875 | F17: =IFERROR(AVERAGEIF(Combined_Data!$G$2:$G$3001,"Remote",Combined_Data!$AF$2:$AF$3001),0) -> 23.228125
A18: India | B18: =COUNTIF(Combined_Data!$G$2:$G$3001,"India") -> 30 | C18: =COUNTIFS(Combined_Data!$G$2:$G$3001,"India",Combined_Data!$AG$2:$AG$3001,"Likely Ghost") -> 0 | D18: =IFERROR(C18/B18*100,0) -> 0 | E18: =IFERROR(AVERAGEIF(Combined_Data!$G$2:$G$3001,"India",Combined_Data!$K$2:$K$3001),0) -> 32.1 | F18: =IFERROR(AVERAGEIF(Combined_Data!$G$2:$G$3001,"India",Combined_Data!$AF$2:$AF$3001),0) -> 21.926667
A19: Navi Mumbai | B19: =COUNTIF(Combined_Data!$G$2:$G$3001,"Navi Mumbai") -> 28 | C19: =COUNTIFS(Combined_Data!$G$2:$G$3001,"Navi Mumbai",Combined_Data!$AG$2:$AG$3001,"Likely Ghost") -> 5 | D19: =IFERROR(C19/B19*100,0) -> 17.857143 | E19: =IFERROR(AVERAGEIF(Combined_Data!$G$2:$G$3001,"Navi Mumbai",Combined_Data!$K$2:$K$3001),0) -> 34.178571 | F19: =IFERROR(AVERAGEIF(Combined_Data!$G$2:$G$3001,"Navi Mumbai",Combined_Data!$AF$2:$AF$3001),0) -> 42.371429
A21: Note: "Not Specified" dominates because many scraped listings omit an explicit city field at source — this is a data-availability artifact, not evidence of ghosting.

Sheet Experience_Contract
A1: Experience Level & Contract Type Analysis
A2: Ghost rate by seniority level and by employment contract type
A4: Experience Level | B4: Total Postings | C4: Likely Ghost | D4: Ghost Rate % | E4: Avg Ghost Score %
A5: Not Captured by Scraper | B5: =COUNTIF(Combined_Data!$M$2:$M$3001,"Not Captured by Scraper") -> 2000 | C5: =COUNTIFS(Combined_Data!$M$2:$M$3001,"Not Captured by Scraper",Combined_Data!$AG$2:$AG$3001,"Likely Ghost") -> 69 | D5: =IFERROR(C5/B5*100,0) -> 3.45 | E5: =IFERROR(AVERAGEIF(Combined_Data!$M$2:$M$3001,"Not Captured by Scraper",Combined_Data!$AF$2:$AF$3001),0) -> 22.9552
A6: Mid-Senior level | B6: =COUNTIF(Combined_Data!$M$2:$M$3001,"Mid-Senior level") -> 579 | C6: =COUNTIFS(Combined_Data!$M$2:$M$3001,"Mid-Senior level",Combined_Data!$AG$2:$AG$3001,"Likely Ghost") -> 77 | D6: =IFERROR(C6/B6*100,0) -> 13.298791 | E6: =IFERROR(AVERAGEIF(Combined_Data!$M$2:$M$3001,"Mid-Senior level",Combined_Data!$AF$2:$AF$3001),0) -> 39.651295
A7: Not Applicable | B7: =COUNTIF(Combined_Data!$M$2:$M$3001,"Not Applicable") -> 295 | C7: =COUNTIFS(Combined_Data!$M$2:$M$3001,"Not Applicable",Combined_Data!$AG$2:$AG$3001,"Likely Ghost") -> 0 | D7: =IFERROR(C7/B7*100,0) -> 0 | E7: =IFERROR(AVERAGEIF(Combined_Data!$M$2:$M$3001,"Not Applicable",Combined_Data!$AF$2:$AF$3001),0) -> 23.170847
A8: Associate | B8: =COUNTIF(Combined_Data!$M$2:$M$3001,"Associate") -> 69 | C8: =COUNTIFS(Combined_Data!$M$2:$M$3001,"Associate",Combined_Data!$AG$2:$AG$3001,"Likely Ghost") -> 0 | D8: =IFERROR(C8/B8*100,0) -> 0 | E8: =IFERROR(AVERAGEIF(Combined_Data!$M$2:$M$3001,"Associate",Combined_Data!$AF$2:$AF$3001),0) -> 24.662319
A9: Entry level | B9: =COUNTIF(Combined_Data!$M$2:$M$3001,"Entry level") -> 44 | C9: =COUNTIFS(Combined_Data!$M$2:$M$3001,"Entry level",Combined_Data!$AG$2:$AG$3001,"Likely Ghost") -> 0 | D9: =IFERROR(C9/B9*100,0) -> 0 | E9: =IFERROR(AVERAGEIF(Combined_Data!$M$2:$M$3001,"Entry level",Combined_Data!$AF$2:$AF$3001),0) -> 30.225
A10: Internship | B10: =COUNTIF(Combined_Data!$M$2:$M$3001,"Internship") -> 8 | C10: =COUNTIFS(Combined_Data!$M$2:$M$3001,"Internship",Combined_Data!$AG$2:$AG$3001,"Likely Ghost") -> 0 | D10: =IFERROR(C10/B10*100,0) -> 0 | E10: =IFERROR(AVERAGEIF(Combined_Data!$M$2:$M$3001,"Internship",Combined_Data!$AF$2:$AF$3001),0) -> 23.2375
A11: Director | B11: =COUNTIF(Combined_Data!$M$2:$M$3001,"Director") -> 4 | C11: =COUNTIFS(Combined_Data!$M$2:$M$3001,"Director",Combined_Data!$AG$2:$AG$3001,"Likely Ghost") -> 0 | D11: =IFERROR(C11/B11*100,0) -> 0 | E11: =IFERROR(AVERAGEIF(Combined_Data!$M$2:$M$3001,"Director",Combined_Data!$AF$2:$AF$3001),0) -> 21.45
